Process ForkPoolWorker-15456:
Traceback (most recent call last):
  File "/usr/lib/python3.9/multiprocessing/pool.py", line 131, in worker
    put((job, i, result))
  File "/usr/lib/python3.9/multiprocessing/queues.py", line 377, in put
    self._writer.send_bytes(obj)
  File "/usr/lib/python3.9/multiprocessing/connection.py", line 205, in send_bytes
    self._send_bytes(m[offset:offset + size])
  File "/usr/lib/python3.9/multiprocessing/connection.py", line 416, in _send_bytes
    self._send(header + buf)
  File "/usr/lib/python3.9/multiprocessing/connection.py", line 373, in _send
    n = write(self._handle, buf)
BrokenPipeError: [Errno 32] Broken pipe

During handling of the above exception, another exception occurred:

Traceback (most recent call last):
  File "/usr/lib/python3.9/multiprocessing/process.py", line 315, in _bootstrap
    self.run()
  File "/usr/lib/python3.9/multiprocessing/process.py", line 108, in run
    self._target(*self._args, **self._kwargs)
  File "/usr/lib/python3.9/multiprocessing/pool.py", line 136, in worker
    put((job, i, (False, wrapped)))
  File "/usr/lib/python3.9/multiprocessing/queues.py", line 377, in put
    self._writer.send_bytes(obj)
  File "/usr/lib/python3.9/multiprocessing/connection.py", line 205, in send_bytes
    self._send_bytes(m[offset:offset + size])
  File "/usr/lib/python3.9/multiprocessing/connection.py", line 416, in _send_bytes
    self._send(header + buf)
  File "/usr/lib/python3.9/multiprocessing/connection.py", line 373, in _send
    n = write(self._handle, buf)
BrokenPipeError: [Errno 32] Broken pipe
Process ForkPoolWorker-15446:
Traceback (most recent call last):
  File "/usr/lib/python3.9/multiprocessing/pool.py", line 131, in worker
    put((job, i, result))
  File "/usr/lib/python3.9/multiprocessing/queues.py", line 377, in put
    self._writer.send_bytes(obj)
  File "/usr/lib/python3.9/multiprocessing/connection.py", line 205, in send_bytes
    self._send_bytes(m[offset:offset + size])
  File "/usr/lib/python3.9/multiprocessing/connection.py", line 416, in _send_bytes
    self._send(header + buf)
  File "/usr/lib/python3.9/multiprocessing/connection.py", line 373, in _send
    n = write(self._handle, buf)
BrokenPipeError: [Errno 32] Broken pipe

During handling of the above exception, another exception occurred:

Traceback (most recent call last):
  File "/usr/lib/python3.9/multiprocessing/process.py", line 315, in _bootstrap
    self.run()
  File "/usr/lib/python3.9/multiprocessing/process.py", line 108, in run
    self._target(*self._args, **self._kwargs)
  File "/usr/lib/python3.9/multiprocessing/pool.py", line 136, in worker
    put((job, i, (False, wrapped)))
  File "/usr/lib/python3.9/multiprocessing/queues.py", line 377, in put
    self._writer.send_bytes(obj)
  File "/usr/lib/python3.9/multiprocessing/connection.py", line 205, in send_bytes
    self._send_bytes(m[offset:offset + size])
  File "/usr/lib/python3.9/multiprocessing/connection.py", line 416, in _send_bytes
    self._send(header + buf)
  File "/usr/lib/python3.9/multiprocessing/connection.py", line 373, in _send
    n = write(self._handle, buf)
BrokenPipeError: [Errno 32] Broken pipe
Process ForkPoolWorker-15448:
Traceback (most recent call last):
  File "/usr/lib/python3.9/multiprocessing/pool.py", line 131, in worker
    put((job, i, result))
  File "/usr/lib/python3.9/multiprocessing/queues.py", line 377, in put
    self._writer.send_bytes(obj)
  File "/usr/lib/python3.9/multiprocessing/connection.py", line 205, in send_bytes
    self._send_bytes(m[offset:offset + size])
  File "/usr/lib/python3.9/multiprocessing/connection.py", line 416, in _send_bytes
    self._send(header + buf)
  File "/usr/lib/python3.9/multiprocessing/connection.py", line 373, in _send
    n = write(self._handle, buf)
BrokenPipeError: [Errno 32] Broken pipe

During handling of the above exception, another exception occurred:

Traceback (most recent call last):
  File "/usr/lib/python3.9/multiprocessing/process.py", line 315, in _bootstrap
    self.run()
  File "/usr/lib/python3.9/multiprocessing/process.py", line 108, in run
    self._target(*self._args, **self._kwargs)
  File "/usr/lib/python3.9/multiprocessing/pool.py", line 136, in worker
    put((job, i, (False, wrapped)))
  File "/usr/lib/python3.9/multiprocessing/queues.py", line 377, in put
    self._writer.send_bytes(obj)
  File "/usr/lib/python3.9/multiprocessing/connection.py", line 205, in send_bytes
    self._send_bytes(m[offset:offset + size])
  File "/usr/lib/python3.9/multiprocessing/connection.py", line 416, in _send_bytes
    self._send(header + buf)
  File "/usr/lib/python3.9/multiprocessing/connection.py", line 373, in _send
    n = write(self._handle, buf)
BrokenPipeError: [Errno 32] Broken pipe
Process ForkPoolWorker-15450:
Traceback (most recent call last):
  File "/usr/lib/python3.9/multiprocessing/pool.py", line 131, in worker
    put((job, i, result))
  File "/usr/lib/python3.9/multiprocessing/queues.py", line 377, in put
    self._writer.send_bytes(obj)
  File "/usr/lib/python3.9/multiprocessing/connection.py", line 205, in send_bytes
    self._send_bytes(m[offset:offset + size])
  File "/usr/lib/python3.9/multiprocessing/connection.py", line 416, in _send_bytes
    self._send(header + buf)
  File "/usr/lib/python3.9/multiprocessing/connection.py", line 373, in _send
    n = write(self._handle, buf)
BrokenPipeError: [Errno 32] Broken pipe

During handling of the above exception, another exception occurred:

Traceback (most recent call last):
  File "/usr/lib/python3.9/multiprocessing/process.py", line 315, in _bootstrap
    self.run()
  File "/usr/lib/python3.9/multiprocessing/process.py", line 108, in run
    self._target(*self._args, **self._kwargs)
  File "/usr/lib/python3.9/multiprocessing/pool.py", line 136, in worker
    put((job, i, (False, wrapped)))
  File "/usr/lib/python3.9/multiprocessing/queues.py", line 377, in put
    self._writer.send_bytes(obj)
  File "/usr/lib/python3.9/multiprocessing/connection.py", line 205, in send_bytes
    self._send_bytes(m[offset:offset + size])
  File "/usr/lib/python3.9/multiprocessing/connection.py", line 416, in _send_bytes
    self._send(header + buf)
  File "/usr/lib/python3.9/multiprocessing/connection.py", line 373, in _send
    n = write(self._handle, buf)
BrokenPipeError: [Errno 32] Broken pipe
Process ForkPoolWorker-15461:
Traceback (most recent call last):
  File "/usr/lib/python3.9/multiprocessing/pool.py", line 131, in worker
    put((job, i, result))
  File "/usr/lib/python3.9/multiprocessing/queues.py", line 377, in put
    self._writer.send_bytes(obj)
  File "/usr/lib/python3.9/multiprocessing/connection.py", line 205, in send_bytes
    self._send_bytes(m[offset:offset + size])
  File "/usr/lib/python3.9/multiprocessing/connection.py", line 416, in _send_bytes
    self._send(header + buf)
  File "/usr/lib/python3.9/multiprocessing/connection.py", line 373, in _send
    n = write(self._handle, buf)
BrokenPipeError: [Errno 32] Broken pipe

During handling of the above exception, another exception occurred:

Traceback (most recent call last):
  File "/usr/lib/python3.9/multiprocessing/process.py", line 315, in _bootstrap
    self.run()
  File "/usr/lib/python3.9/multiprocessing/process.py", line 108, in run
    self._target(*self._args, **self._kwargs)
  File "/usr/lib/python3.9/multiprocessing/pool.py", line 136, in worker
    put((job, i, (False, wrapped)))
  File "/usr/lib/python3.9/multiprocessing/queues.py", line 377, in put
    self._writer.send_bytes(obj)
  File "/usr/lib/python3.9/multiprocessing/connection.py", line 205, in send_bytes
    self._send_bytes(m[offset:offset + size])
  File "/usr/lib/python3.9/multiprocessing/connection.py", line 416, in _send_bytes
    self._send(header + buf)
  File "/usr/lib/python3.9/multiprocessing/connection.py", line 373, in _send
    n = write(self._handle, buf)
BrokenPipeError: [Errno 32] Broken pipe
Process ForkPoolWorker-15463:
Traceback (most recent call last):
  File "/usr/lib/python3.9/multiprocessing/pool.py", line 131, in worker
    put((job, i, result))
  File "/usr/lib/python3.9/multiprocessing/queues.py", line 377, in put
    self._writer.send_bytes(obj)
  File "/usr/lib/python3.9/multiprocessing/connection.py", line 205, in send_bytes
    self._send_bytes(m[offset:offset + size])
  File "/usr/lib/python3.9/multiprocessing/connection.py", line 416, in _send_bytes
    self._send(header + buf)
  File "/usr/lib/python3.9/multiprocessing/connection.py", line 373, in _send
    n = write(self._handle, buf)
BrokenPipeError: [Errno 32] Broken pipe

During handling of the above exception, another exception occurred:

Traceback (most recent call last):
  File "/usr/lib/python3.9/multiprocessing/process.py", line 315, in _bootstrap
    self.run()
  File "/usr/lib/python3.9/multiprocessing/process.py", line 108, in run
    self._target(*self._args, **self._kwargs)
  File "/usr/lib/python3.9/multiprocessing/pool.py", line 136, in worker
    put((job, i, (False, wrapped)))
  File "/usr/lib/python3.9/multiprocessing/queues.py", line 377, in put
    self._writer.send_bytes(obj)
  File "/usr/lib/python3.9/multiprocessing/connection.py", line 205, in send_bytes
    self._send_bytes(m[offset:offset + size])
  File "/usr/lib/python3.9/multiprocessing/connection.py", line 416, in _send_bytes
    self._send(header + buf)
  File "/usr/lib/python3.9/multiprocessing/connection.py", line 373, in _send
    n = write(self._handle, buf)
BrokenPipeError: [Errno 32] Broken pipe
Process ForkPoolWorker-15454:
Traceback (most recent call last):
  File "/usr/lib/python3.9/multiprocessing/pool.py", line 131, in worker
    put((job, i, result))
  File "/usr/lib/python3.9/multiprocessing/queues.py", line 377, in put
    self._writer.send_bytes(obj)
  File "/usr/lib/python3.9/multiprocessing/connection.py", line 205, in send_bytes
    self._send_bytes(m[offset:offset + size])
  File "/usr/lib/python3.9/multiprocessing/connection.py", line 416, in _send_bytes
    self._send(header + buf)
  File "/usr/lib/python3.9/multiprocessing/connection.py", line 373, in _send
    n = write(self._handle, buf)
BrokenPipeError: [Errno 32] Broken pipe

During handling of the above exception, another exception occurred:

Traceback (most recent call last):
  File "/usr/lib/python3.9/multiprocessing/process.py", line 315, in _bootstrap
    self.run()
  File "/usr/lib/python3.9/multiprocessing/process.py", line 108, in run
    self._target(*self._args, **self._kwargs)
  File "/usr/lib/python3.9/multiprocessing/pool.py", line 136, in worker
    put((job, i, (False, wrapped)))
  File "/usr/lib/python3.9/multiprocessing/queues.py", line 377, in put
    self._writer.send_bytes(obj)
  File "/usr/lib/python3.9/multiprocessing/connection.py", line 205, in send_bytes
    self._send_bytes(m[offset:offset + size])
  File "/usr/lib/python3.9/multiprocessing/connection.py", line 416, in _send_bytes
    self._send(header + buf)
  File "/usr/lib/python3.9/multiprocessing/connection.py", line 373, in _send
    n = write(self._handle, buf)
BrokenPipeError: [Errno 32] Broken pipe
Process ForkPoolWorker-15459:
Traceback (most recent call last):
  File "/usr/lib/python3.9/multiprocessing/pool.py", line 131, in worker
    put((job, i, result))
  File "/usr/lib/python3.9/multiprocessing/queues.py", line 377, in put
    self._writer.send_bytes(obj)
  File "/usr/lib/python3.9/multiprocessing/connection.py", line 205, in send_bytes
    self._send_bytes(m[offset:offset + size])
  File "/usr/lib/python3.9/multiprocessing/connection.py", line 416, in _send_bytes
    self._send(header + buf)
  File "/usr/lib/python3.9/multiprocessing/connection.py", line 373, in _send
    n = write(self._handle, buf)
BrokenPipeError: [Errno 32] Broken pipe

During handling of the above exception, another exception occurred:

Traceback (most recent call last):
  File "/usr/lib/python3.9/multiprocessing/process.py", line 315, in _bootstrap
    self.run()
  File "/usr/lib/python3.9/multiprocessing/process.py", line 108, in run
    self._target(*self._args, **self._kwargs)
  File "/usr/lib/python3.9/multiprocessing/pool.py", line 136, in worker
    put((job, i, (False, wrapped)))
  File "/usr/lib/python3.9/multiprocessing/queues.py", line 377, in put
    self._writer.send_bytes(obj)
  File "/usr/lib/python3.9/multiprocessing/connection.py", line 205, in send_bytes
    self._send_bytes(m[offset:offset + size])
  File "/usr/lib/python3.9/multiprocessing/connection.py", line 416, in _send_bytes
    self._send(header + buf)
  File "/usr/lib/python3.9/multiprocessing/connection.py", line 373, in _send
    n = write(self._handle, buf)
BrokenPipeError: [Errno 32] Broken pipe
Process ForkPoolWorker-15442:
Traceback (most recent call last):
  File "/usr/lib/python3.9/multiprocessing/pool.py", line 131, in worker
    put((job, i, result))
  File "/usr/lib/python3.9/multiprocessing/queues.py", line 377, in put
    self._writer.send_bytes(obj)
  File "/usr/lib/python3.9/multiprocessing/connection.py", line 205, in send_bytes
    self._send_bytes(m[offset:offset + size])
  File "/usr/lib/python3.9/multiprocessing/connection.py", line 416, in _send_bytes
    self._send(header + buf)
  File "/usr/lib/python3.9/multiprocessing/connection.py", line 373, in _send
    n = write(self._handle, buf)
BrokenPipeError: [Errno 32] Broken pipe

During handling of the above exception, another exception occurred:

Traceback (most recent call last):
  File "/usr/lib/python3.9/multiprocessing/process.py", line 315, in _bootstrap
    self.run()
  File "/usr/lib/python3.9/multiprocessing/process.py", line 108, in run
    self._target(*self._args, **self._kwargs)
  File "/usr/lib/python3.9/multiprocessing/pool.py", line 136, in worker
    put((job, i, (False, wrapped)))
  File "/usr/lib/python3.9/multiprocessing/queues.py", line 377, in put
    self._writer.send_bytes(obj)
  File "/usr/lib/python3.9/multiprocessing/connection.py", line 205, in send_bytes
    self._send_bytes(m[offset:offset + size])
  File "/usr/lib/python3.9/multiprocessing/connection.py", line 416, in _send_bytes
    self._send(header + buf)
  File "/usr/lib/python3.9/multiprocessing/connection.py", line 373, in _send
    n = write(self._handle, buf)
BrokenPipeError: [Errno 32] Broken pipe
Process ForkPoolWorker-15445:
Traceback (most recent call last):
  File "/usr/lib/python3.9/multiprocessing/pool.py", line 131, in worker
    put((job, i, result))
  File "/usr/lib/python3.9/multiprocessing/queues.py", line 377, in put
    self._writer.send_bytes(obj)
  File "/usr/lib/python3.9/multiprocessing/connection.py", line 205, in send_bytes
    self._send_bytes(m[offset:offset + size])
  File "/usr/lib/python3.9/multiprocessing/connection.py", line 416, in _send_bytes
    self._send(header + buf)
  File "/usr/lib/python3.9/multiprocessing/connection.py", line 373, in _send
    n = write(self._handle, buf)
BrokenPipeError: [Errno 32] Broken pipe

During handling of the above exception, another exception occurred:

Traceback (most recent call last):
  File "/usr/lib/python3.9/multiprocessing/process.py", line 315, in _bootstrap
    self.run()
  File "/usr/lib/python3.9/multiprocessing/process.py", line 108, in run
    self._target(*self._args, **self._kwargs)
  File "/usr/lib/python3.9/multiprocessing/pool.py", line 136, in worker
    put((job, i, (False, wrapped)))
  File "/usr/lib/python3.9/multiprocessing/queues.py", line 377, in put
    self._writer.send_bytes(obj)
  File "/usr/lib/python3.9/multiprocessing/connection.py", line 205, in send_bytes
    self._send_bytes(m[offset:offset + size])
  File "/usr/lib/python3.9/multiprocessing/connection.py", line 416, in _send_bytes
    self._send(header + buf)
  File "/usr/lib/python3.9/multiprocessing/connection.py", line 373, in _send
    n = write(self._handle, buf)
BrokenPipeError: [Errno 32] Broken pipe
Process ForkPoolWorker-15458:
Traceback (most recent call last):
  File "/usr/lib/python3.9/multiprocessing/pool.py", line 131, in worker
    put((job, i, result))
  File "/usr/lib/python3.9/multiprocessing/queues.py", line 377, in put
    self._writer.send_bytes(obj)
  File "/usr/lib/python3.9/multiprocessing/connection.py", line 205, in send_bytes
    self._send_bytes(m[offset:offset + size])
  File "/usr/lib/python3.9/multiprocessing/connection.py", line 416, in _send_bytes
    self._send(header + buf)
  File "/usr/lib/python3.9/multiprocessing/connection.py", line 373, in _send
    n = write(self._handle, buf)
BrokenPipeError: [Errno 32] Broken pipe

During handling of the above exception, another exception occurred:

Traceback (most recent call last):
  File "/usr/lib/python3.9/multiprocessing/process.py", line 315, in _bootstrap
    self.run()
  File "/usr/lib/python3.9/multiprocessing/process.py", line 108, in run
    self._target(*self._args, **self._kwargs)
  File "/usr/lib/python3.9/multiprocessing/pool.py", line 136, in worker
    put((job, i, (False, wrapped)))
  File "/usr/lib/python3.9/multiprocessing/queues.py", line 377, in put
    self._writer.send_bytes(obj)
  File "/usr/lib/python3.9/multiprocessing/connection.py", line 205, in send_bytes
    self._send_bytes(m[offset:offset + size])
  File "/usr/lib/python3.9/multiprocessing/connection.py", line 416, in _send_bytes
    self._send(header + buf)
  File "/usr/lib/python3.9/multiprocessing/connection.py", line 373, in _send
    n = write(self._handle, buf)
BrokenPipeError: [Errno 32] Broken pipe
Process ForkPoolWorker-15462:
Traceback (most recent call last):
  File "/usr/lib/python3.9/multiprocessing/pool.py", line 131, in worker
    put((job, i, result))
  File "/usr/lib/python3.9/multiprocessing/queues.py", line 377, in put
    self._writer.send_bytes(obj)
  File "/usr/lib/python3.9/multiprocessing/connection.py", line 205, in send_bytes
    self._send_bytes(m[offset:offset + size])
  File "/usr/lib/python3.9/multiprocessing/connection.py", line 416, in _send_bytes
    self._send(header + buf)
  File "/usr/lib/python3.9/multiprocessing/connection.py", line 373, in _send
    n = write(self._handle, buf)
BrokenPipeError: [Errno 32] Broken pipe

During handling of the above exception, another exception occurred:

Traceback (most recent call last):
  File "/usr/lib/python3.9/multiprocessing/process.py", line 315, in _bootstrap
    self.run()
  File "/usr/lib/python3.9/multiprocessing/process.py", line 108, in run
    self._target(*self._args, **self._kwargs)
  File "/usr/lib/python3.9/multiprocessing/pool.py", line 136, in worker
    put((job, i, (False, wrapped)))
  File "/usr/lib/python3.9/multiprocessing/queues.py", line 377, in put
    self._writer.send_bytes(obj)
  File "/usr/lib/python3.9/multiprocessing/connection.py", line 205, in send_bytes
    self._send_bytes(m[offset:offset + size])
  File "/usr/lib/python3.9/multiprocessing/connection.py", line 416, in _send_bytes
    self._send(header + buf)
  File "/usr/lib/python3.9/multiprocessing/connection.py", line 373, in _send
    n = write(self._handle, buf)
BrokenPipeError: [Errno 32] Broken pipe
Process ForkPoolWorker-15440:
Traceback (most recent call last):
  File "/usr/lib/python3.9/multiprocessing/pool.py", line 131, in worker
    put((job, i, result))
  File "/usr/lib/python3.9/multiprocessing/queues.py", line 377, in put
    self._writer.send_bytes(obj)
  File "/usr/lib/python3.9/multiprocessing/connection.py", line 205, in send_bytes
    self._send_bytes(m[offset:offset + size])
  File "/usr/lib/python3.9/multiprocessing/connection.py", line 416, in _send_bytes
    self._send(header + buf)
  File "/usr/lib/python3.9/multiprocessing/connection.py", line 373, in _send
    n = write(self._handle, buf)
BrokenPipeError: [Errno 32] Broken pipe

During handling of the above exception, another exception occurred:

Traceback (most recent call last):
  File "/usr/lib/python3.9/multiprocessing/process.py", line 315, in _bootstrap
    self.run()
  File "/usr/lib/python3.9/multiprocessing/process.py", line 108, in run
    self._target(*self._args, **self._kwargs)
  File "/usr/lib/python3.9/multiprocessing/pool.py", line 136, in worker
    put((job, i, (False, wrapped)))
  File "/usr/lib/python3.9/multiprocessing/queues.py", line 377, in put
    self._writer.send_bytes(obj)
  File "/usr/lib/python3.9/multiprocessing/connection.py", line 205, in send_bytes
    self._send_bytes(m[offset:offset + size])
  File "/usr/lib/python3.9/multiprocessing/connection.py", line 416, in _send_bytes
    self._send(header + buf)
  File "/usr/lib/python3.9/multiprocessing/connection.py", line 373, in _send
    n = write(self._handle, buf)
BrokenPipeError: [Errno 32] Broken pipe
Process ForkPoolWorker-15460:
Traceback (most recent call last):
  File "/usr/lib/python3.9/multiprocessing/pool.py", line 131, in worker
    put((job, i, result))
  File "/usr/lib/python3.9/multiprocessing/queues.py", line 377, in put
    self._writer.send_bytes(obj)
  File "/usr/lib/python3.9/multiprocessing/connection.py", line 205, in send_bytes
    self._send_bytes(m[offset:offset + size])
  File "/usr/lib/python3.9/multiprocessing/connection.py", line 416, in _send_bytes
    self._send(header + buf)
  File "/usr/lib/python3.9/multiprocessing/connection.py", line 373, in _send
    n = write(self._handle, buf)
BrokenPipeError: [Errno 32] Broken pipe

During handling of the above exception, another exception occurred:

Traceback (most recent call last):
  File "/usr/lib/python3.9/multiprocessing/process.py", line 315, in _bootstrap
    self.run()
  File "/usr/lib/python3.9/multiprocessing/process.py", line 108, in run
    self._target(*self._args, **self._kwargs)
  File "/usr/lib/python3.9/multiprocessing/pool.py", line 136, in worker
    put((job, i, (False, wrapped)))
  File "/usr/lib/python3.9/multiprocessing/queues.py", line 377, in put
    self._writer.send_bytes(obj)
  File "/usr/lib/python3.9/multiprocessing/connection.py", line 205, in send_bytes
    self._send_bytes(m[offset:offset + size])
  File "/usr/lib/python3.9/multiprocessing/connection.py", line 416, in _send_bytes
    self._send(header + buf)
  File "/usr/lib/python3.9/multiprocessing/connection.py", line 373, in _send
    n = write(self._handle, buf)
BrokenPipeError: [Errno 32] Broken pipe
Process ForkPoolWorker-15443:
Traceback (most recent call last):
  File "/usr/lib/python3.9/multiprocessing/pool.py", line 131, in worker
    put((job, i, result))
  File "/usr/lib/python3.9/multiprocessing/queues.py", line 377, in put
    self._writer.send_bytes(obj)
  File "/usr/lib/python3.9/multiprocessing/connection.py", line 205, in send_bytes
    self._send_bytes(m[offset:offset + size])
  File "/usr/lib/python3.9/multiprocessing/connection.py", line 416, in _send_bytes
    self._send(header + buf)
  File "/usr/lib/python3.9/multiprocessing/connection.py", line 373, in _send
    n = write(self._handle, buf)
BrokenPipeError: [Errno 32] Broken pipe

During handling of the above exception, another exception occurred:

Traceback (most recent call last):
  File "/usr/lib/python3.9/multiprocessing/process.py", line 315, in _bootstrap
    self.run()
  File "/usr/lib/python3.9/multiprocessing/process.py", line 108, in run
    self._target(*self._args, **self._kwargs)
  File "/usr/lib/python3.9/multiprocessing/pool.py", line 136, in worker
    put((job, i, (False, wrapped)))
  File "/usr/lib/python3.9/multiprocessing/queues.py", line 377, in put
    self._writer.send_bytes(obj)
  File "/usr/lib/python3.9/multiprocessing/connection.py", line 205, in send_bytes
    self._send_bytes(m[offset:offset + size])
  File "/usr/lib/python3.9/multiprocessing/connection.py", line 416, in _send_bytes
    self._send(header + buf)
  File "/usr/lib/python3.9/multiprocessing/connection.py", line 373, in _send
    n = write(self._handle, buf)
BrokenPipeError: [Errno 32] Broken pipe
Process ForkPoolWorker-15444:
Traceback (most recent call last):
  File "/usr/lib/python3.9/multiprocessing/pool.py", line 131, in worker
    put((job, i, result))
  File "/usr/lib/python3.9/multiprocessing/queues.py", line 377, in put
    self._writer.send_bytes(obj)
  File "/usr/lib/python3.9/multiprocessing/connection.py", line 205, in send_bytes
    self._send_bytes(m[offset:offset + size])
  File "/usr/lib/python3.9/multiprocessing/connection.py", line 416, in _send_bytes
    self._send(header + buf)
  File "/usr/lib/python3.9/multiprocessing/connection.py", line 373, in _send
    n = write(self._handle, buf)
BrokenPipeError: [Errno 32] Broken pipe

During handling of the above exception, another exception occurred:

Traceback (most recent call last):
  File "/usr/lib/python3.9/multiprocessing/process.py", line 315, in _bootstrap
    self.run()
  File "/usr/lib/python3.9/multiprocessing/process.py", line 108, in run
    self._target(*self._args, **self._kwargs)
  File "/usr/lib/python3.9/multiprocessing/pool.py", line 136, in worker
    put((job, i, (False, wrapped)))
  File "/usr/lib/python3.9/multiprocessing/queues.py", line 377, in put
    self._writer.send_bytes(obj)
  File "/usr/lib/python3.9/multiprocessing/connection.py", line 205, in send_bytes
    self._send_bytes(m[offset:offset + size])
  File "/usr/lib/python3.9/multiprocessing/connection.py", line 416, in _send_bytes
    self._send(header + buf)
  File "/usr/lib/python3.9/multiprocessing/connection.py", line 373, in _send
    n = write(self._handle, buf)
BrokenPipeError: [Errno 32] Broken pipe
Process ForkPoolWorker-15441:
Traceback (most recent call last):
  File "/usr/lib/python3.9/multiprocessing/pool.py", line 131, in worker
    put((job, i, result))
  File "/usr/lib/python3.9/multiprocessing/queues.py", line 377, in put
    self._writer.send_bytes(obj)
  File "/usr/lib/python3.9/multiprocessing/connection.py", line 205, in send_bytes
    self._send_bytes(m[offset:offset + size])
  File "/usr/lib/python3.9/multiprocessing/connection.py", line 416, in _send_bytes
    self._send(header + buf)
  File "/usr/lib/python3.9/multiprocessing/connection.py", line 373, in _send
    n = write(self._handle, buf)
BrokenPipeError: [Errno 32] Broken pipe

During handling of the above exception, another exception occurred:

Traceback (most recent call last):
  File "/usr/lib/python3.9/multiprocessing/process.py", line 315, in _bootstrap
    self.run()
  File "/usr/lib/python3.9/multiprocessing/process.py", line 108, in run
    self._target(*self._args, **self._kwargs)
  File "/usr/lib/python3.9/multiprocessing/pool.py", line 136, in worker
    put((job, i, (False, wrapped)))
  File "/usr/lib/python3.9/multiprocessing/queues.py", line 377, in put
    self._writer.send_bytes(obj)
  File "/usr/lib/python3.9/multiprocessing/connection.py", line 205, in send_bytes
    self._send_bytes(m[offset:offset + size])
  File "/usr/lib/python3.9/multiprocessing/connection.py", line 416, in _send_bytes
    self._send(header + buf)
  File "/usr/lib/python3.9/multiprocessing/connection.py", line 373, in _send
    n = write(self._handle, buf)
BrokenPipeError: [Errno 32] Broken pipe
Process ForkPoolWorker-15457:
Traceback (most recent call last):
  File "/usr/lib/python3.9/multiprocessing/pool.py", line 131, in worker
    put((job, i, result))
  File "/usr/lib/python3.9/multiprocessing/queues.py", line 377, in put
    self._writer.send_bytes(obj)
  File "/usr/lib/python3.9/multiprocessing/connection.py", line 205, in send_bytes
    self._send_bytes(m[offset:offset + size])
  File "/usr/lib/python3.9/multiprocessing/connection.py", line 416, in _send_bytes
    self._send(header + buf)
  File "/usr/lib/python3.9/multiprocessing/connection.py", line 373, in _send
    n = write(self._handle, buf)
BrokenPipeError: [Errno 32] Broken pipe

During handling of the above exception, another exception occurred:

Traceback (most recent call last):
  File "/usr/lib/python3.9/multiprocessing/process.py", line 315, in _bootstrap
    self.run()
  File "/usr/lib/python3.9/multiprocessing/process.py", line 108, in run
    self._target(*self._args, **self._kwargs)
  File "/usr/lib/python3.9/multiprocessing/pool.py", line 136, in worker
    put((job, i, (False, wrapped)))
  File "/usr/lib/python3.9/multiprocessing/queues.py", line 377, in put
    self._writer.send_bytes(obj)
  File "/usr/lib/python3.9/multiprocessing/connection.py", line 205, in send_bytes
    self._send_bytes(m[offset:offset + size])
  File "/usr/lib/python3.9/multiprocessing/connection.py", line 416, in _send_bytes
    self._send(header + buf)
  File "/usr/lib/python3.9/multiprocessing/connection.py", line 373, in _send
    n = write(self._handle, buf)
BrokenPipeError: [Errno 32] Broken pipe
Process ForkPoolWorker-15449:
Traceback (most recent call last):
  File "/usr/lib/python3.9/multiprocessing/pool.py", line 131, in worker
    put((job, i, result))
  File "/usr/lib/python3.9/multiprocessing/queues.py", line 377, in put
    self._writer.send_bytes(obj)
  File "/usr/lib/python3.9/multiprocessing/connection.py", line 205, in send_bytes
    self._send_bytes(m[offset:offset + size])
  File "/usr/lib/python3.9/multiprocessing/connection.py", line 416, in _send_bytes
    self._send(header + buf)
  File "/usr/lib/python3.9/multiprocessing/connection.py", line 373, in _send
    n = write(self._handle, buf)
BrokenPipeError: [Errno 32] Broken pipe

During handling of the above exception, another exception occurred:

Traceback (most recent call last):
  File "/usr/lib/python3.9/multiprocessing/process.py", line 315, in _bootstrap
    self.run()
  File "/usr/lib/python3.9/multiprocessing/process.py", line 108, in run
    self._target(*self._args, **self._kwargs)
  File "/usr/lib/python3.9/multiprocessing/pool.py", line 136, in worker
    put((job, i, (False, wrapped)))
  File "/usr/lib/python3.9/multiprocessing/queues.py", line 377, in put
    self._writer.send_bytes(obj)
  File "/usr/lib/python3.9/multiprocessing/connection.py", line 205, in send_bytes
    self._send_bytes(m[offset:offset + size])
  File "/usr/lib/python3.9/multiprocessing/connection.py", line 416, in _send_bytes
    self._send(header + buf)
  File "/usr/lib/python3.9/multiprocessing/connection.py", line 373, in _send
    n = write(self._handle, buf)
BrokenPipeError: [Errno 32] Broken pipe
Process ForkPoolWorker-15452:
Traceback (most recent call last):
  File "/usr/lib/python3.9/multiprocessing/pool.py", line 131, in worker
    put((job, i, result))
  File "/usr/lib/python3.9/multiprocessing/queues.py", line 377, in put
    self._writer.send_bytes(obj)
  File "/usr/lib/python3.9/multiprocessing/connection.py", line 205, in send_bytes
    self._send_bytes(m[offset:offset + size])
  File "/usr/lib/python3.9/multiprocessing/connection.py", line 416, in _send_bytes
    self._send(header + buf)
  File "/usr/lib/python3.9/multiprocessing/connection.py", line 373, in _send
    n = write(self._handle, buf)
BrokenPipeError: [Errno 32] Broken pipe

During handling of the above exception, another exception occurred:

Traceback (most recent call last):
  File "/usr/lib/python3.9/multiprocessing/process.py", line 315, in _bootstrap
    self.run()
  File "/usr/lib/python3.9/multiprocessing/process.py", line 108, in run
    self._target(*self._args, **self._kwargs)
  File "/usr/lib/python3.9/multiprocessing/pool.py", line 136, in worker
    put((job, i, (False, wrapped)))
  File "/usr/lib/python3.9/multiprocessing/queues.py", line 377, in put
    self._writer.send_bytes(obj)
  File "/usr/lib/python3.9/multiprocessing/connection.py", line 205, in send_bytes
    self._send_bytes(m[offset:offset + size])
  File "/usr/lib/python3.9/multiprocessing/connection.py", line 416, in _send_bytes
    self._send(header + buf)
  File "/usr/lib/python3.9/multiprocessing/connection.py", line 373, in _send
    n = write(self._handle, buf)
BrokenPipeError: [Errno 32] Broken pipe
Process ForkPoolWorker-15447:
Traceback (most recent call last):
  File "/usr/lib/python3.9/multiprocessing/pool.py", line 131, in worker
    put((job, i, result))
  File "/usr/lib/python3.9/multiprocessing/queues.py", line 377, in put
    self._writer.send_bytes(obj)
  File "/usr/lib/python3.9/multiprocessing/connection.py", line 205, in send_bytes
    self._send_bytes(m[offset:offset + size])
  File "/usr/lib/python3.9/multiprocessing/connection.py", line 416, in _send_bytes
    self._send(header + buf)
  File "/usr/lib/python3.9/multiprocessing/connection.py", line 373, in _send
    n = write(self._handle, buf)
BrokenPipeError: [Errno 32] Broken pipe

During handling of the above exception, another exception occurred:

Traceback (most recent call last):
  File "/usr/lib/python3.9/multiprocessing/process.py", line 315, in _bootstrap
    self.run()
  File "/usr/lib/python3.9/multiprocessing/process.py", line 108, in run
    self._target(*self._args, **self._kwargs)
  File "/usr/lib/python3.9/multiprocessing/pool.py", line 136, in worker
    put((job, i, (False, wrapped)))
  File "/usr/lib/python3.9/multiprocessing/queues.py", line 377, in put
    self._writer.send_bytes(obj)
  File "/usr/lib/python3.9/multiprocessing/connection.py", line 205, in send_bytes
    self._send_bytes(m[offset:offset + size])
  File "/usr/lib/python3.9/multiprocessing/connection.py", line 416, in _send_bytes
    self._send(header + buf)
  File "/usr/lib/python3.9/multiprocessing/connection.py", line 373, in _send
    n = write(self._handle, buf)
BrokenPipeError: [Errno 32] Broken pipe
Process ForkPoolWorker-15453:
Traceback (most recent call last):
  File "/usr/lib/python3.9/multiprocessing/pool.py", line 131, in worker
    put((job, i, result))
  File "/usr/lib/python3.9/multiprocessing/queues.py", line 377, in put
    self._writer.send_bytes(obj)
  File "/usr/lib/python3.9/multiprocessing/connection.py", line 205, in send_bytes
    self._send_bytes(m[offset:offset + size])
  File "/usr/lib/python3.9/multiprocessing/connection.py", line 416, in _send_bytes
    self._send(header + buf)
  File "/usr/lib/python3.9/multiprocessing/connection.py", line 373, in _send
    n = write(self._handle, buf)
BrokenPipeError: [Errno 32] Broken pipe

During handling of the above exception, another exception occurred:

Traceback (most recent call last):
  File "/usr/lib/python3.9/multiprocessing/process.py", line 315, in _bootstrap
    self.run()
  File "/usr/lib/python3.9/multiprocessing/process.py", line 108, in run
    self._target(*self._args, **self._kwargs)
  File "/usr/lib/python3.9/multiprocessing/pool.py", line 136, in worker
    put((job, i, (False, wrapped)))
  File "/usr/lib/python3.9/multiprocessing/queues.py", line 377, in put
    self._writer.send_bytes(obj)
  File "/usr/lib/python3.9/multiprocessing/connection.py", line 205, in send_bytes
    self._send_bytes(m[offset:offset + size])
  File "/usr/lib/python3.9/multiprocessing/connection.py", line 416, in _send_bytes
    self._send(header + buf)
  File "/usr/lib/python3.9/multiprocessing/connection.py", line 373, in _send
    n = write(self._handle, buf)
BrokenPipeError: [Errno 32] Broken pipe
Process ForkPoolWorker-15455:
Traceback (most recent call last):
  File "/usr/lib/python3.9/multiprocessing/pool.py", line 131, in worker
    put((job, i, result))
  File "/usr/lib/python3.9/multiprocessing/queues.py", line 377, in put
    self._writer.send_bytes(obj)
  File "/usr/lib/python3.9/multiprocessing/connection.py", line 205, in send_bytes
    self._send_bytes(m[offset:offset + size])
  File "/usr/lib/python3.9/multiprocessing/connection.py", line 416, in _send_bytes
    self._send(header + buf)
  File "/usr/lib/python3.9/multiprocessing/connection.py", line 373, in _send
    n = write(self._handle, buf)
BrokenPipeError: [Errno 32] Broken pipe

During handling of the above exception, another exception occurred:

Traceback (most recent call last):
  File "/usr/lib/python3.9/multiprocessing/process.py", line 315, in _bootstrap
    self.run()
  File "/usr/lib/python3.9/multiprocessing/process.py", line 108, in run
    self._target(*self._args, **self._kwargs)
  File "/usr/lib/python3.9/multiprocessing/pool.py", line 136, in worker
    put((job, i, (False, wrapped)))
  File "/usr/lib/python3.9/multiprocessing/queues.py", line 377, in put
    self._writer.send_bytes(obj)
  File "/usr/lib/python3.9/multiprocessing/connection.py", line 205, in send_bytes
    self._send_bytes(m[offset:offset + size])
  File "/usr/lib/python3.9/multiprocessing/connection.py", line 416, in _send_bytes
    self._send(header + buf)
  File "/usr/lib/python3.9/multiprocessing/connection.py", line 373, in _send
    n = write(self._handle, buf)
BrokenPipeError: [Errno 32] Broken pipe
Process ForkPoolWorker-15451:
Traceback (most recent call last):
  File "/usr/lib/python3.9/multiprocessing/pool.py", line 131, in worker
    put((job, i, result))
  File "/usr/lib/python3.9/multiprocessing/queues.py", line 377, in put
    self._writer.send_bytes(obj)
  File "/usr/lib/python3.9/multiprocessing/connection.py", line 205, in send_bytes
    self._send_bytes(m[offset:offset + size])
  File "/usr/lib/python3.9/multiprocessing/connection.py", line 416, in _send_bytes
    self._send(header + buf)
  File "/usr/lib/python3.9/multiprocessing/connection.py", line 373, in _send
    n = write(self._handle, buf)
BrokenPipeError: [Errno 32] Broken pipe

During handling of the above exception, another exception occurred:

Traceback (most recent call last):
  File "/usr/lib/python3.9/multiprocessing/process.py", line 315, in _bootstrap
    self.run()
  File "/usr/lib/python3.9/multiprocessing/process.py", line 108, in run
    self._target(*self._args, **self._kwargs)
  File "/usr/lib/python3.9/multiprocessing/pool.py", line 136, in worker
    put((job, i, (False, wrapped)))
  File "/usr/lib/python3.9/multiprocessing/queues.py", line 377, in put
    self._writer.send_bytes(obj)
  File "/usr/lib/python3.9/multiprocessing/connection.py", line 205, in send_bytes
    self._send_bytes(m[offset:offset + size])
  File "/usr/lib/python3.9/multiprocessing/connection.py", line 416, in _send_bytes
    self._send(header + buf)
  File "/usr/lib/python3.9/multiprocessing/connection.py", line 373, in _send
    n = write(self._handle, buf)
BrokenPipeError: [Errno 32] Broken pipe
